Traceback (most recent call last):
  File "/root/news_site_scraper/kempinski.py", line 5, in <module>
    driver = webdriver.Chrome()
  File "/usr/local/lib/python3.10/dist-packages/selenium/webdriver/chrome/webdriver.py", line 45, in __init__
    super().__init__(
  File "/usr/local/lib/python3.10/dist-packages/selenium/webdriver/chromium/webdriver.py", line 66, in __init__
    super().__init__(command_executor=executor, options=options)
  File "/usr/local/lib/python3.10/dist-packages/selenium/webdriver/remote/webdriver.py", line 241, in __init__
    self.start_session(capabilities)
  File "/usr/local/lib/python3.10/dist-packages/selenium/webdriver/remote/webdriver.py", line 329, in start_session
    response = self.execute(Command.NEW_SESSION, caps)["value"]
  File "/usr/local/lib/python3.10/dist-packages/selenium/webdriver/remote/webdriver.py", line 384, in execute
    self.error_handler.check_response(response)
  File "/usr/local/lib/python3.10/dist-packages/selenium/webdriver/remote/errorhandler.py", line 232, in check_response
    raise exception_class(message, screen, stacktrace)
selenium.common.exceptions.SessionNotCreatedException: Message: session not created: Chrome failed to start: exited normally.
  (session not created: DevToolsActivePort file doesn't exist)
  (The process started from chrome location /usr/bin/google-chrome is no longer running, so ChromeDriver is assuming that Chrome has crashed.)
Stacktrace:
#0 0x55e756d348fa <unknown>
#1 0x55e756845d20 <unknown>
#2 0x55e75687d438 <unknown>
#3 0x55e756878f96 <unknown>
#4 0x55e7568c4d86 <unknown>
#5 0x55e7568c43d6 <unknown>
#6 0x55e7568b8893 <unknown>
#7 0x55e75688730d <unknown>
#8 0x55e75688832e <unknown>
#9 0x55e756d0100b <unknown>
#10 0x55e756d04f97 <unknown>
#11 0x55e756ced71c <unknown>
#12 0x55e756d05b17 <unknown>
#13 0x55e756cd26cf <unknown>
#14 0x55e756d236b8 <unknown>
#15 0x55e756d23880 <unknown>
#16 0x55e756d33776 <unknown>
#17 0x7f44414feac3 <unknown>

Traceback (most recent call last):
  File "/root/news_site_scraper/kempinski.py", line 5, in <module>
    driver = webdriver.Chrome()
  File "/usr/local/lib/python3.10/dist-packages/selenium/webdriver/chrome/webdriver.py", line 45, in __init__
    super().__init__(
  File "/usr/local/lib/python3.10/dist-packages/selenium/webdriver/chromium/webdriver.py", line 66, in __init__
    super().__init__(command_executor=executor, options=options)
  File "/usr/local/lib/python3.10/dist-packages/selenium/webdriver/remote/webdriver.py", line 241, in __init__
    self.start_session(capabilities)
  File "/usr/local/lib/python3.10/dist-packages/selenium/webdriver/remote/webdriver.py", line 329, in start_session
    response = self.execute(Command.NEW_SESSION, caps)["value"]
  File "/usr/local/lib/python3.10/dist-packages/selenium/webdriver/remote/webdriver.py", line 384, in execute
    self.error_handler.check_response(response)
  File "/usr/local/lib/python3.10/dist-packages/selenium/webdriver/remote/errorhandler.py", line 232, in check_response
    raise exception_class(message, screen, stacktrace)
selenium.common.exceptions.SessionNotCreatedException: Message: session not created: Chrome failed to start: exited normally.
  (session not created: DevToolsActivePort file doesn't exist)
  (The process started from chrome location /usr/bin/google-chrome is no longer running, so ChromeDriver is assuming that Chrome has crashed.)
Stacktrace:
#0 0x5590cc1418fa <unknown>
#1 0x5590cbc52d20 <unknown>
#2 0x5590cbc8a438 <unknown>
#3 0x5590cbc85f96 <unknown>
#4 0x5590cbcd1d86 <unknown>
#5 0x5590cbcd13d6 <unknown>
#6 0x5590cbcc5893 <unknown>
#7 0x5590cbc9430d <unknown>
#8 0x5590cbc9532e <unknown>
#9 0x5590cc10e00b <unknown>
#10 0x5590cc111f97 <unknown>
#11 0x5590cc0fa71c <unknown>
#12 0x5590cc112b17 <unknown>
#13 0x5590cc0df6cf <unknown>
#14 0x5590cc1306b8 <unknown>
#15 0x5590cc130880 <unknown>
#16 0x5590cc140776 <unknown>
#17 0x7f74978c9ac3 <unknown>

Traceback (most recent call last):
  File "/root/news_site_scraper/kempinski.py", line 5, in <module>
    driver = webdriver.Chrome()
  File "/usr/local/lib/python3.10/dist-packages/selenium/webdriver/chrome/webdriver.py", line 45, in __init__
    super().__init__(
  File "/usr/local/lib/python3.10/dist-packages/selenium/webdriver/chromium/webdriver.py", line 66, in __init__
    super().__init__(command_executor=executor, options=options)
  File "/usr/local/lib/python3.10/dist-packages/selenium/webdriver/remote/webdriver.py", line 241, in __init__
    self.start_session(capabilities)
  File "/usr/local/lib/python3.10/dist-packages/selenium/webdriver/remote/webdriver.py", line 329, in start_session
    response = self.execute(Command.NEW_SESSION, caps)["value"]
  File "/usr/local/lib/python3.10/dist-packages/selenium/webdriver/remote/webdriver.py", line 384, in execute
    self.error_handler.check_response(response)
  File "/usr/local/lib/python3.10/dist-packages/selenium/webdriver/remote/errorhandler.py", line 232, in check_response
    raise exception_class(message, screen, stacktrace)
selenium.common.exceptions.SessionNotCreatedException: Message: session not created: Chrome failed to start: exited normally.
  (session not created: DevToolsActivePort file doesn't exist)
  (The process started from chrome location /usr/bin/google-chrome is no longer running, so ChromeDriver is assuming that Chrome has crashed.)
Stacktrace:
#0 0x55ac850b18fa <unknown>
#1 0x55ac84bc2d20 <unknown>
#2 0x55ac84bfa438 <unknown>
#3 0x55ac84bf5f96 <unknown>
#4 0x55ac84c41d86 <unknown>
#5 0x55ac84c413d6 <unknown>
#6 0x55ac84c35893 <unknown>
#7 0x55ac84c0430d <unknown>
#8 0x55ac84c0532e <unknown>
#9 0x55ac8507e00b <unknown>
#10 0x55ac85081f97 <unknown>
#11 0x55ac8506a71c <unknown>
#12 0x55ac85082b17 <unknown>
#13 0x55ac8504f6cf <unknown>
#14 0x55ac850a06b8 <unknown>
#15 0x55ac850a0880 <unknown>
#16 0x55ac850b0776 <unknown>
#17 0x7f703f162ac3 <unknown>

Traceback (most recent call last):
  File "/root/news_site_scraper/kempinski.py", line 5, in <module>
    driver = webdriver.Chrome()
  File "/usr/local/lib/python3.10/dist-packages/selenium/webdriver/chrome/webdriver.py", line 45, in __init__
    super().__init__(
  File "/usr/local/lib/python3.10/dist-packages/selenium/webdriver/chromium/webdriver.py", line 66, in __init__
    super().__init__(command_executor=executor, options=options)
  File "/usr/local/lib/python3.10/dist-packages/selenium/webdriver/remote/webdriver.py", line 241, in __init__
    self.start_session(capabilities)
  File "/usr/local/lib/python3.10/dist-packages/selenium/webdriver/remote/webdriver.py", line 329, in start_session
    response = self.execute(Command.NEW_SESSION, caps)["value"]
  File "/usr/local/lib/python3.10/dist-packages/selenium/webdriver/remote/webdriver.py", line 384, in execute
    self.error_handler.check_response(response)
  File "/usr/local/lib/python3.10/dist-packages/selenium/webdriver/remote/errorhandler.py", line 232, in check_response
    raise exception_class(message, screen, stacktrace)
selenium.common.exceptions.SessionNotCreatedException: Message: session not created: Chrome failed to start: exited normally.
  (session not created: DevToolsActivePort file doesn't exist)
  (The process started from chrome location /usr/bin/google-chrome is no longer running, so ChromeDriver is assuming that Chrome has crashed.)
Stacktrace:
#0 0x56185ec358fa <unknown>
#1 0x56185e746d20 <unknown>
#2 0x56185e77e438 <unknown>
#3 0x56185e779f96 <unknown>
#4 0x56185e7c5d86 <unknown>
#5 0x56185e7c53d6 <unknown>
#6 0x56185e7b9893 <unknown>
#7 0x56185e78830d <unknown>
#8 0x56185e78932e <unknown>
#9 0x56185ec0200b <unknown>
#10 0x56185ec05f97 <unknown>
#11 0x56185ebee71c <unknown>
#12 0x56185ec06b17 <unknown>
#13 0x56185ebd36cf <unknown>
#14 0x56185ec246b8 <unknown>
#15 0x56185ec24880 <unknown>
#16 0x56185ec34776 <unknown>
#17 0x7ff7c59abac3 <unknown>

Traceback (most recent call last):
  File "/root/news_site_scraper/kempinski.py", line 5, in <module>
    driver = webdriver.Chrome()
  File "/usr/local/lib/python3.10/dist-packages/selenium/webdriver/chrome/webdriver.py", line 45, in __init__
    super().__init__(
  File "/usr/local/lib/python3.10/dist-packages/selenium/webdriver/chromium/webdriver.py", line 66, in __init__
    super().__init__(command_executor=executor, options=options)
  File "/usr/local/lib/python3.10/dist-packages/selenium/webdriver/remote/webdriver.py", line 241, in __init__
    self.start_session(capabilities)
  File "/usr/local/lib/python3.10/dist-packages/selenium/webdriver/remote/webdriver.py", line 329, in start_session
    response = self.execute(Command.NEW_SESSION, caps)["value"]
  File "/usr/local/lib/python3.10/dist-packages/selenium/webdriver/remote/webdriver.py", line 384, in execute
    self.error_handler.check_response(response)
  File "/usr/local/lib/python3.10/dist-packages/selenium/webdriver/remote/errorhandler.py", line 232, in check_response
    raise exception_class(message, screen, stacktrace)
selenium.common.exceptions.SessionNotCreatedException: Message: session not created: Chrome failed to start: exited normally.
  (session not created: DevToolsActivePort file doesn't exist)
  (The process started from chrome location /usr/bin/google-chrome is no longer running, so ChromeDriver is assuming that Chrome has crashed.)
Stacktrace:
#0 0x55596e16e8fa <unknown>
#1 0x55596dc7fd20 <unknown>
#2 0x55596dcb7438 <unknown>
#3 0x55596dcb2f96 <unknown>
#4 0x55596dcfed86 <unknown>
#5 0x55596dcfe3d6 <unknown>
#6 0x55596dcf2893 <unknown>
#7 0x55596dcc130d <unknown>
#8 0x55596dcc232e <unknown>
#9 0x55596e13b00b <unknown>
#10 0x55596e13ef97 <unknown>
#11 0x55596e12771c <unknown>
#12 0x55596e13fb17 <unknown>
#13 0x55596e10c6cf <unknown>
#14 0x55596e15d6b8 <unknown>
#15 0x55596e15d880 <unknown>
#16 0x55596e16d776 <unknown>
#17 0x7fa8c3759ac3 <unknown>

Traceback (most recent call last):
  File "/root/news_site_scraper/kempinski.py", line 5, in <module>
    driver = webdriver.Chrome()
  File "/usr/local/lib/python3.10/dist-packages/selenium/webdriver/chrome/webdriver.py", line 45, in __init__
    super().__init__(
  File "/usr/local/lib/python3.10/dist-packages/selenium/webdriver/chromium/webdriver.py", line 66, in __init__
    super().__init__(command_executor=executor, options=options)
  File "/usr/local/lib/python3.10/dist-packages/selenium/webdriver/remote/webdriver.py", line 241, in __init__
    self.start_session(capabilities)
  File "/usr/local/lib/python3.10/dist-packages/selenium/webdriver/remote/webdriver.py", line 329, in start_session
    response = self.execute(Command.NEW_SESSION, caps)["value"]
  File "/usr/local/lib/python3.10/dist-packages/selenium/webdriver/remote/webdriver.py", line 384, in execute
    self.error_handler.check_response(response)
  File "/usr/local/lib/python3.10/dist-packages/selenium/webdriver/remote/errorhandler.py", line 232, in check_response
    raise exception_class(message, screen, stacktrace)
selenium.common.exceptions.SessionNotCreatedException: Message: session not created: Chrome failed to start: exited normally.
  (session not created: DevToolsActivePort file doesn't exist)
  (The process started from chrome location /usr/bin/google-chrome is no longer running, so ChromeDriver is assuming that Chrome has crashed.)
Stacktrace:
#0 0x55b7113758fa <unknown>
#1 0x55b710e86d20 <unknown>
#2 0x55b710ebe438 <unknown>
#3 0x55b710eb9f96 <unknown>
#4 0x55b710f05d86 <unknown>
#5 0x55b710f053d6 <unknown>
#6 0x55b710ef9893 <unknown>
#7 0x55b710ec830d <unknown>
#8 0x55b710ec932e <unknown>
#9 0x55b71134200b <unknown>
#10 0x55b711345f97 <unknown>
#11 0x55b71132e71c <unknown>
#12 0x55b711346b17 <unknown>
#13 0x55b7113136cf <unknown>
#14 0x55b7113646b8 <unknown>
#15 0x55b711364880 <unknown>
#16 0x55b711374776 <unknown>
#17 0x7f4e91cffac3 <unknown>

Traceback (most recent call last):
  File "/root/news_site_scraper/kempinski.py", line 5, in <module>
    driver = webdriver.Chrome()
  File "/usr/local/lib/python3.10/dist-packages/selenium/webdriver/chrome/webdriver.py", line 45, in __init__
    super().__init__(
  File "/usr/local/lib/python3.10/dist-packages/selenium/webdriver/chromium/webdriver.py", line 66, in __init__
    super().__init__(command_executor=executor, options=options)
  File "/usr/local/lib/python3.10/dist-packages/selenium/webdriver/remote/webdriver.py", line 241, in __init__
    self.start_session(capabilities)
  File "/usr/local/lib/python3.10/dist-packages/selenium/webdriver/remote/webdriver.py", line 329, in start_session
    response = self.execute(Command.NEW_SESSION, caps)["value"]
  File "/usr/local/lib/python3.10/dist-packages/selenium/webdriver/remote/webdriver.py", line 384, in execute
    self.error_handler.check_response(response)
  File "/usr/local/lib/python3.10/dist-packages/selenium/webdriver/remote/errorhandler.py", line 232, in check_response
    raise exception_class(message, screen, stacktrace)
selenium.common.exceptions.SessionNotCreatedException: Message: session not created: Chrome failed to start: exited normally.
  (session not created: DevToolsActivePort file doesn't exist)
  (The process started from chrome location /usr/bin/google-chrome is no longer running, so ChromeDriver is assuming that Chrome has crashed.)
Stacktrace:
#0 0x55ffea3818fa <unknown>
#1 0x55ffe9e92d20 <unknown>
#2 0x55ffe9eca438 <unknown>
#3 0x55ffe9ec5f96 <unknown>
#4 0x55ffe9f11d86 <unknown>
#5 0x55ffe9f113d6 <unknown>
#6 0x55ffe9f05893 <unknown>
#7 0x55ffe9ed430d <unknown>
#8 0x55ffe9ed532e <unknown>
#9 0x55ffea34e00b <unknown>
#10 0x55ffea351f97 <unknown>
#11 0x55ffea33a71c <unknown>
#12 0x55ffea352b17 <unknown>
#13 0x55ffea31f6cf <unknown>
#14 0x55ffea3706b8 <unknown>
#15 0x55ffea370880 <unknown>
#16 0x55ffea380776 <unknown>
#17 0x7f96917ccac3 <unknown>

